2025-05-03 14:43:03,195 - INFO - C:\Users\dipak\OneDrive\Desktop\chat_dj_pro\level_one_three\book_club\bookclub_project\apps\users\views.py changed, reloading.
2025-05-03 14:45:15,573 - INFO - C:\Users\dipak\OneDrive\Desktop\chat_dj_pro\level_one_three\book_club\bookclub_project\apps\users\views.py changed, reloading.
2025-05-03 14:48:35,493 - INFO - C:\Users\dipak\OneDrive\Desktop\chat_dj_pro\level_one_three\book_club\bookclub_project\apps\users\views.py changed, reloading.
2025-05-03 14:48:40,099 - INFO - C:\Users\dipak\OneDrive\Desktop\chat_dj_pro\level_one_three\book_club\bookclub_project\apps\users\views.py changed, reloading.
2025-05-03 14:49:48,800 - INFO - C:\Users\dipak\OneDrive\Desktop\chat_dj_pro\level_one_three\book_club\bookclub_project\apps\users\views.py changed, reloading.
2025-05-03 14:49:50,993 - INFO - C:\Users\dipak\OneDrive\Desktop\chat_dj_pro\level_one_three\book_club\bookclub_project\apps\users\views.py changed, reloading.
2025-05-03 14:50:09,218 - WARNING - Not Found: /favicon.ico
2025-05-03 14:50:24,739 - ERROR - Internal Server Error: /home/login_view
Traceback (most recent call last):
  File "C:\Users\dipak\anaconda3\Lib\site-packages\django\core\handlers\exception.py", line 55, in inner
    response = get_response(request)
               ^^^^^^^^^^^^^^^^^^^^^
  File "C:\Users\dipak\anaconda3\Lib\site-packages\django\core\handlers\base.py", line 197, in _get_response
    response = wrapped_callback(request, *callback_args, **callback_kwargs)
               ^^^^^^^^^^^^^^^^^^^^^^^^^^^^^^^^^^^^^^^^^^^^^^^^^^^^^^^^^^^^
  File "C:\Users\dipak\OneDrive\desktop\chat_dj_pro\level_one_three\book_club\bookclub_project\apps\users\views.py", line 34, in login_view
    username= Users.objects.get(user_email)
              ^^^^^^^^^^^^^^^^^^^^^^^^^^^^^
  File "C:\Users\dipak\anaconda3\Lib\site-packages\django\db\models\manager.py", line 87, in manager_method
    return getattr(self.get_queryset(), name)(*args, **kwargs)
           ^^^^^^^^^^^^^^^^^^^^^^^^^^^^^^^^^^^^^^^^^^^^^^^^^^^
  File "C:\Users\dipak\anaconda3\Lib\site-packages\django\db\models\query.py", line 635, in get
    clone = self._chain() if self.query.combinator else self.filter(*args, **kwargs)
                                                        ^^^^^^^^^^^^^^^^^^^^^^^^^^^^
  File "C:\Users\dipak\anaconda3\Lib\site-packages\django\db\models\query.py", line 1476, in filter
    return self._filter_or_exclude(False, args, kwargs)
           ^^^^^^^^^^^^^^^^^^^^^^^^^^^^^^^^^^^^^^^^^^^^
  File "C:\Users\dipak\anaconda3\Lib\site-packages\django\db\models\query.py", line 1494, in _filter_or_exclude
    clone._filter_or_exclude_inplace(negate, args, kwargs)
  File "C:\Users\dipak\anaconda3\Lib\site-packages\django\db\models\query.py", line 1501, in _filter_or_exclude_inplace
    self._query.add_q(Q(*args, **kwargs))
  File "C:\Users\dipak\anaconda3\Lib\site-packages\django\db\models\sql\query.py", line 1609, in add_q
    clause, _ = self._add_q(q_object, self.used_aliases)
                ^^^^^^^^^^^^^^^^^^^^^^^^^^^^^^^^^^^^^^^^
  File "C:\Users\dipak\anaconda3\Lib\site-packages\django\db\models\sql\query.py", line 1641, in _add_q
    child_clause, needed_inner = self.build_filter(
                                 ^^^^^^^^^^^^^^^^^^
  File "C:\Users\dipak\anaconda3\Lib\site-packages\django\db\models\sql\query.py", line 1488, in build_filter
    arg, value = filter_expr
    ^^^^^^^^^^
ValueError: too many values to unpack (expected 2)
2025-05-03 14:51:47,769 - INFO - C:\Users\dipak\OneDrive\Desktop\chat_dj_pro\level_one_three\book_club\bookclub_project\apps\users\views.py changed, reloading.
2025-05-03 14:52:20,779 - INFO - C:\Users\dipak\OneDrive\Desktop\chat_dj_pro\level_one_three\book_club\bookclub_project\apps\users\views.py changed, reloading.
2025-05-03 14:52:32,365 - INFO - C:\Users\dipak\OneDrive\Desktop\chat_dj_pro\level_one_three\book_club\bookclub_project\apps\users\views.py changed, reloading.
2025-05-03 14:52:34,585 - INFO - C:\Users\dipak\OneDrive\Desktop\chat_dj_pro\level_one_three\book_club\bookclub_project\apps\users\views.py changed, reloading.
2025-05-03 14:56:36,783 - INFO - C:\Users\dipak\OneDrive\Desktop\chat_dj_pro\level_one_three\book_club\bookclub_project\apps\users\models.py changed, reloading.
2025-05-03 14:58:19,061 - INFO - C:\Users\dipak\OneDrive\Desktop\chat_dj_pro\level_one_three\book_club\bookclub_project\apps\users\models.py changed, reloading.
2025-05-03 14:58:25,403 - INFO - C:\Users\dipak\OneDrive\Desktop\chat_dj_pro\level_one_three\book_club\bookclub_project\apps\users\models.py changed, reloading.
2025-05-03 14:59:42,306 - INFO - C:\Users\dipak\OneDrive\Desktop\chat_dj_pro\level_one_three\book_club\bookclub_project\apps\users\models.py changed, reloading.
2025-05-03 15:01:13,308 - INFO - C:\Users\dipak\OneDrive\Desktop\chat_dj_pro\level_one_three\book_club\bookclub_project\bookclub_project\settings.py changed, reloading.
2025-05-03 15:02:19,315 - INFO - C:\Users\dipak\OneDrive\Desktop\chat_dj_pro\level_one_three\book_club\bookclub_project\apps\users\models.py changed, reloading.
2025-05-03 15:02:21,684 - INFO - C:\Users\dipak\OneDrive\Desktop\chat_dj_pro\level_one_three\book_club\bookclub_project\apps\users\models.py changed, reloading.
2025-05-03 16:05:00,811 - ERROR - Internal Server Error: /admin/login/
Traceback (most recent call last):
  File "C:\Users\dipak\anaconda3\Lib\site-packages\django\db\backends\utils.py", line 105, in _execute
    return self.cursor.execute(sql, params)
           ^^^^^^^^^^^^^^^^^^^^^^^^^^^^^^^^
  File "C:\Users\dipak\anaconda3\Lib\site-packages\django\db\backends\sqlite3\base.py", line 354, in execute
    return super().execute(query, params)
           ^^^^^^^^^^^^^^^^^^^^^^^^^^^^^^
sqlite3.OperationalError: no such table: users_users

The above exception was the direct cause of the following exception:

Traceback (most recent call last):
  File "C:\Users\dipak\anaconda3\Lib\site-packages\django\core\handlers\exception.py", line 55, in inner
    response = get_response(request)
               ^^^^^^^^^^^^^^^^^^^^^
  File "C:\Users\dipak\anaconda3\Lib\site-packages\django\core\handlers\base.py", line 197, in _get_response
    response = wrapped_callback(request, *callback_args, **callback_kwargs)
               ^^^^^^^^^^^^^^^^^^^^^^^^^^^^^^^^^^^^^^^^^^^^^^^^^^^^^^^^^^^^
  File "C:\Users\dipak\anaconda3\Lib\site-packages\django\utils\decorators.py", line 48, in _wrapper
    return bound_method(*args, **kwargs)
           ^^^^^^^^^^^^^^^^^^^^^^^^^^^^^
  File "C:\Users\dipak\anaconda3\Lib\site-packages\django\views\decorators\cache.py", line 80, in _view_wrapper
    response = view_func(request, *args, **kwargs)
               ^^^^^^^^^^^^^^^^^^^^^^^^^^^^^^^^^^^
  File "C:\Users\dipak\anaconda3\Lib\site-packages\django\contrib\admin\sites.py", line 444, in login
    return LoginView.as_view(**defaults)(request)
           ^^^^^^^^^^^^^^^^^^^^^^^^^^^^^^^^^^^^^^
  File "C:\Users\dipak\anaconda3\Lib\site-packages\django\views\generic\base.py", line 104, in view
    return self.dispatch(request, *args, **kwargs)
           ^^^^^^^^^^^^^^^^^^^^^^^^^^^^^^^^^^^^^^^
  File "C:\Users\dipak\anaconda3\Lib\site-packages\django\utils\decorators.py", line 48, in _wrapper
    return bound_method(*args, **kwargs)
           ^^^^^^^^^^^^^^^^^^^^^^^^^^^^^
  File "C:\Users\dipak\anaconda3\Lib\site-packages\django\utils\decorators.py", line 48, in _wrapper
    return bound_method(*args, **kwargs)
           ^^^^^^^^^^^^^^^^^^^^^^^^^^^^^
  File "C:\Users\dipak\anaconda3\Lib\site-packages\django\views\decorators\debug.py", line 143, in sensitive_post_parameters_wrapper
    return view(request, *args, **kwargs)
           ^^^^^^^^^^^^^^^^^^^^^^^^^^^^^^
  File "C:\Users\dipak\anaconda3\Lib\site-packages\django\utils\decorators.py", line 48, in _wrapper
    return bound_method(*args, **kwargs)
           ^^^^^^^^^^^^^^^^^^^^^^^^^^^^^
  File "C:\Users\dipak\anaconda3\Lib\site-packages\django\utils\decorators.py", line 188, in _view_wrapper
    result = _process_exception(request, e)
             ^^^^^^^^^^^^^^^^^^^^^^^^^^^^^^
  File "C:\Users\dipak\anaconda3\Lib\site-packages\django\utils\decorators.py", line 186, in _view_wrapper
    response = view_func(request, *args, **kwargs)
               ^^^^^^^^^^^^^^^^^^^^^^^^^^^^^^^^^^^
  File "C:\Users\dipak\anaconda3\Lib\site-packages\django\utils\decorators.py", line 48, in _wrapper
    return bound_method(*args, **kwargs)
           ^^^^^^^^^^^^^^^^^^^^^^^^^^^^^
  File "C:\Users\dipak\anaconda3\Lib\site-packages\django\views\decorators\cache.py", line 80, in _view_wrapper
    response = view_func(request, *args, **kwargs)
               ^^^^^^^^^^^^^^^^^^^^^^^^^^^^^^^^^^^
  File "C:\Users\dipak\anaconda3\Lib\site-packages\django\contrib\auth\views.py", line 89, in dispatch
    return super().dispatch(request, *args, **kwargs)
           ^^^^^^^^^^^^^^^^^^^^^^^^^^^^^^^^^^^^^^^^^^
  File "C:\Users\dipak\anaconda3\Lib\site-packages\django\views\generic\base.py", line 143, in dispatch
    return handler(request, *args, **kwargs)
           ^^^^^^^^^^^^^^^^^^^^^^^^^^^^^^^^^
  File "C:\Users\dipak\anaconda3\Lib\site-packages\django\views\generic\edit.py", line 150, in post
    if form.is_valid():
       ^^^^^^^^^^^^^^^
  File "C:\Users\dipak\anaconda3\Lib\site-packages\django\forms\forms.py", line 197, in is_valid
    return self.is_bound and not self.errors
                                 ^^^^^^^^^^^
  File "C:\Users\dipak\anaconda3\Lib\site-packages\django\forms\forms.py", line 192, in errors
    self.full_clean()
  File "C:\Users\dipak\anaconda3\Lib\site-packages\django\forms\forms.py", line 326, in full_clean
    self._clean_form()
  File "C:\Users\dipak\anaconda3\Lib\site-packages\django\forms\forms.py", line 342, in _clean_form
    cleaned_data = self.clean()
                   ^^^^^^^^^^^^
  File "C:\Users\dipak\anaconda3\Lib\site-packages\django\contrib\auth\forms.py", line 356, in clean
    self.user_cache = authenticate(
                      ^^^^^^^^^^^^^
  File "C:\Users\dipak\anaconda3\Lib\site-packages\django\views\decorators\debug.py", line 75, in sensitive_variables_wrapper
    return func(*func_args, **func_kwargs)
           ^^^^^^^^^^^^^^^^^^^^^^^^^^^^^^^
  File "C:\Users\dipak\anaconda3\Lib\site-packages\django\contrib\auth\__init__.py", line 79, in authenticate
    user = backend.authenticate(request, **credentials)
           ^^^^^^^^^^^^^^^^^^^^^^^^^^^^^^^^^^^^^^^^^^^^
  File "C:\Users\dipak\anaconda3\Lib\site-packages\django\contrib\auth\backends.py", line 42, in authenticate
    user = UserModel._default_manager.get_by_natural_key(username)
           ^^^^^^^^^^^^^^^^^^^^^^^^^^^^^^^^^^^^^^^^^^^^^^^^^^^^^^^
  File "C:\Users\dipak\anaconda3\Lib\site-packages\django\contrib\auth\base_user.py", line 37, in get_by_natural_key
    return self.get(**{self.model.USERNAME_FIELD: username})
           ^^^^^^^^^^^^^^^^^^^^^^^^^^^^^^^^^^^^^^^^^^^^^^^^^
  File "C:\Users\dipak\anaconda3\Lib\site-packages\django\db\models\manager.py", line 87, in manager_method
    return getattr(self.get_queryset(), name)(*args, **kwargs)
           ^^^^^^^^^^^^^^^^^^^^^^^^^^^^^^^^^^^^^^^^^^^^^^^^^^^
  File "C:\Users\dipak\anaconda3\Lib\site-packages\django\db\models\query.py", line 645, in get
    num = len(clone)
          ^^^^^^^^^^
  File "C:\Users\dipak\anaconda3\Lib\site-packages\django\db\models\query.py", line 382, in __len__
    self._fetch_all()
  File "C:\Users\dipak\anaconda3\Lib\site-packages\django\db\models\query.py", line 1928, in _fetch_all
    self._result_cache = list(self._iterable_class(self))
                         ^^^^^^^^^^^^^^^^^^^^^^^^^^^^^^^^
  File "C:\Users\dipak\anaconda3\Lib\site-packages\django\db\models\query.py", line 91, in __iter__
    results = compiler.execute_sql(
              ^^^^^^^^^^^^^^^^^^^^^
  File "C:\Users\dipak\anaconda3\Lib\site-packages\django\db\models\sql\compiler.py", line 1574, in execute_sql
    cursor.execute(sql, params)
  File "C:\Users\dipak\anaconda3\Lib\site-packages\django\db\backends\utils.py", line 122, in execute
    return super().execute(sql, params)
           ^^^^^^^^^^^^^^^^^^^^^^^^^^^^
  File "C:\Users\dipak\anaconda3\Lib\site-packages\django\db\backends\utils.py", line 79, in execute
    return self._execute_with_wrappers(
           ^^^^^^^^^^^^^^^^^^^^^^^^^^^^
  File "C:\Users\dipak\anaconda3\Lib\site-packages\django\db\backends\utils.py", line 92, in _execute_with_wrappers
    return executor(sql, params, many, context)
           ^^^^^^^^^^^^^^^^^^^^^^^^^^^^^^^^^^^^
  File "C:\Users\dipak\anaconda3\Lib\site-packages\django\db\backends\utils.py", line 100, in _execute
    with self.db.wrap_database_errors:
  File "C:\Users\dipak\anaconda3\Lib\site-packages\django\db\utils.py", line 91, in __exit__
    raise dj_exc_value.with_traceback(traceback) from exc_value
  File "C:\Users\dipak\anaconda3\Lib\site-packages\django\db\backends\utils.py", line 105, in _execute
    return self.cursor.execute(sql, params)
           ^^^^^^^^^^^^^^^^^^^^^^^^^^^^^^^^
  File "C:\Users\dipak\anaconda3\Lib\site-packages\django\db\backends\sqlite3\base.py", line 354, in execute
    return super().execute(query, params)
           ^^^^^^^^^^^^^^^^^^^^^^^^^^^^^^
django.db.utils.OperationalError: no such table: users_users
2025-05-03 16:27:03,683 - WARNING - Not Found: /admin/auth/user/
2025-05-03 16:28:05,044 - WARNING - Forbidden (CSRF token from POST incorrect.): /home/login_view
2025-05-03 17:29:13,174 - ERROR - Internal Server Error: /home/login_view
Traceback (most recent call last):
  File "C:\Users\dipak\anaconda3\Lib\site-packages\django\core\handlers\exception.py", line 55, in inner
    response = get_response(request)
               ^^^^^^^^^^^^^^^^^^^^^
  File "C:\Users\dipak\anaconda3\Lib\site-packages\django\core\handlers\base.py", line 197, in _get_response
    response = wrapped_callback(request, *callback_args, **callback_kwargs)
               ^^^^^^^^^^^^^^^^^^^^^^^^^^^^^^^^^^^^^^^^^^^^^^^^^^^^^^^^^^^^
  File "C:\Users\dipak\OneDrive\desktop\chat_dj_pro\level_one_three\book_club\bookclub_project\apps\users\views.py", line 44, in login_view
    if authenticate(request, user_name, password):
       ^^^^^^^^^^^^^^^^^^^^^^^^^^^^^^^^^^^^^^^^^^
  File "C:\Users\dipak\anaconda3\Lib\site-packages\django\views\decorators\debug.py", line 75, in sensitive_variables_wrapper
    return func(*func_args, **func_kwargs)
           ^^^^^^^^^^^^^^^^^^^^^^^^^^^^^^^
TypeError: authenticate() takes from 0 to 1 positional arguments but 3 were given
2025-05-03 17:33:42,097 - INFO - C:\Users\dipak\OneDrive\Desktop\chat_dj_pro\level_one_three\book_club\bookclub_project\apps\users\views.py changed, reloading.
